Workbook
Name List_Bool: Tableau_Bool[Boolean]
Name List_Bool: Tableau_Bool[Boolean]
Name List_Bool: Tableau_Bool[Boolean]
Name List_PCR: Tableau_PCR[PCR]
Name List_PCR: Tableau_PCR[PCR]
Name List_PCR: Tableau_PCR[PCR]
Name List_PSR: Tableau_PSR[PSR]
Name List_PSR: Tableau_PSR[PSR]
Name List_PSR: Tableau_PSR[PSR]
Name List_SendMode: Tableau_SendMode[Send mode]
Name List_SendMode: Tableau_SendMode[Send mode]
Name List_SendMode: Tableau_SendMode[Send mode]
Name List_Units: Tableau_Units[Units]
Name List_Units: Tableau_Units[Units]
Name List_Units: Tableau_Units[Units]
Name List_Units_Mass: Tableau_Units_Mass[Units]
Name List_Units_Mass: Tableau_Units_Mass[Units]
Name List_Units_Mass: Tableau_Units_Mass[Units]
Name List_Zone: Tableau_Zone[Zone]
Name List_Zone: Tableau_Zone[Zone]
Name List_Zone: Tableau_Zone[Zone]

Sheet PEP Declaration
B1: General Informations | Y1: Homogeneous Environmental Family | AA1: Bill of Material | AT1: Administrative Informations | BE1: Declared Product | BK1: Distribution
A2: Property : | B2: Register Number | C2: Name of PEP | D2: ID AUTO | E2: Product Classification (Level 1) | F2: ID AUTO | G2: Category (Level 2) | H2: ID AUTO | I2: Family (Level 3) | J2: ID AUTO | K2: Solution (Level 4) | L2: Product Reference | M2: Functional-Unit Description | N2: Functional-Unit Quantity | O2: ID AUTO | P2: Functional-Unit Unit | Q2: Date of publication | R2: ID AUTO | S2: Related PCR | T2: ID AUTO | U2: Related PSR | V2: Use Life-time | W2: unused | X2: Energy Model Used | Y2: Covered products by list | Z2: Covered products or brand by text | AA2: Total mass | AB2: ID AUTO | AC2: Total mass Unit | AD2: Product Mass | AE2: Product Mass Unit | AF2: Packaging Mass | AG2: Packaging Mass Unit | AH2: Additional Elements Mass | AI2: Additional Elements Mass Unit | AJ2: Kg of Plastic | AK2: Kg of Metal | AL2: Kg of Other | AM2: Kg Total | AN2: Percent of Plastic | AO2: Percent of Metal | AP2: Percent of Other | AQ2: Percent Total | AR2: Comments of BOM | AS2: UF Extrapolation rules | AT2: Technical-Contact First name | AU2: Technical-Contact Last name | AV2: Technical-Contact Email | AW2: Billing-Contact First name | AX2: Billing-Contact Last name | AY2: Billing-Contact Email | AZ2: Verificator Number | BA2: Author | BB2: Submitter Name | BC2: Order Number | BD2: Is it a Joint PEP? | BE2: Is PEP about declared product? | BF2: Declared product Description | BG2: Declared product Quantity | BH2: ID AUTO | BI2: Declared product Unit | BJ2: Declared product ExtraRules | BK2: Distribute Pep to the Website ? | BL2: ID AUTO | BM2: Send the PEP to Inies ? | BN2: ID AUTO | BO2: Is PEP available on API ? | BP2: ID AUTO | BQ2: Is PEP available on Ecoplatform ? | BR2: Tags
A3: Format to respect : | B3: Format : AAAA-bbbbb-Vxx.yy-cc | C3: No format : Free text | D3: Automatic : don't change ! | E3: Select an item from the DropDownList only, and don't change the text selected. The selection of an item, will filter the next list (Category) | F3: Automatic : don't change ! | G3: Select an item from the DropDownList only, and don't change the text selected. The selection of an item, will filter the next list (Family) | H3: Automatic : don't change ! | I3: Select an item from the DropDownList only, and don't change the text selected. The selection of an item, will filter the next list (Solution) | J3: Automatic : don't change ! | K3: Select an item from the DropDownList only, and don't change the text selected. The selection of an item, will filter the next list (Category) | L3: No format : free text | M3: No format : free text | N3: Integer number only | O3: Automatic : don't change ! | P3: Select an item from the DropDownList only, and don't change the text selected. | Q3: Date only according to the Excel format | R3: Automatic : don't change ! | S3: Select an item from the DropDownList only, and don't change the text selected. | T3: Automatic : don't change ! | U3: Select an item from the DropDownList only, and don't change the text selected. | V3: Integer number only | W3: unused | X3: No format : free text | Y3: One commercial reference by line ("alt+enter" for new line) | Z3: No format : free text | AA3: Decimal only | AB3: Automatic : don't change ! | AC3: Only kg allowed | AE3: Only kg allowed | AG3: Only kg allowed | AI3: Only kg allowed | AJ3: Decimal only | AK3: Decimal only | AL3: Decimal only | AM3: Calculated total | AN3: Percentage (max 2 decimals) | AO3: Percentage (max 2 decimals) | AP3: Percentage (max 2 decimals) | AQ3: Calculated verification : Must be 100,00 % ! | AR3: No format : free text | AS3: No format : free text | AT3: No format : free text | AV3: Format : email@domain.com | AW3: No format : free text | AX3: No format : free text | AY3: Format : email@domain.com | AZ3: Format : "VH00" | BA3: No format : free text | BB3: No format : free text | BC3: No format : free text | BD3: Select an item from the DropDownList only. | BE3: Select an item from the DropDownList only. | BF3: No format : free text | BG3: Integer only | BH3: Automatic : don't change ! | BI3: Select an item from the DropDownList only. | BJ3: No format : free text | BK3: Select an item from the DropDownList only. | BL3: Automatic : don't change ! | BM3: Select an item from the DropDownList only. | BN3: Automatic : don't change ! | BO3: Select an item from the DropDownList only. | BP3: Automatic : don't change ! | BQ3: Select an item from the DropDownList only. | BR3: One tag by line ("alt+enter" for new line)
A4: Your PEP Declaration : | D4: =IF(_xlfn.XLOOKUP($E$4,Level1!B:B,Level1!A:A,"")=0,"",_xlfn.XLOOKUP($E$4,Level1!B:B,Level1!A:A,"")) | F4: =_xlfn.XLOOKUP($G$4,Level2!B:B,Level2!A:A,"") -> 0 | H4: =_xlfn.XLOOKUP($I$4,Level3!B:B,Level3!A:A,"") -> 0 | J4: =_xlfn.XLOOKUP($K$4,Level4!B:B,Level4!A:A,"") -> 0 | O4: =_xlfn.XLOOKUP($P$4,Tableau_Units[Units],Tableau_Units[code],"") | R4: =_xlfn.XLOOKUP($S$4,Tableau_PCR[PCR],Tableau_PCR[Code],"") | T4: =_xlfn.XLOOKUP($U$4,Tableau_PSR[PSR],Tableau_PSR[Code],"") | W4: =_xlfn.XLOOKUP($X$4,Tableau_Zone[Zone],Tableau_Zone[Code],"") | AB4: =_xlfn.XLOOKUP($AC$4,Tableau_Units_Mass[Units],Tableau_Units_Mass[code],"") | AM4: =AL4+AK4+AJ4 -> 0 | AQ4: =(AP4+AO4+AN4)/100 -> 0 | BH4: =_xlfn.XLOOKUP($BI$4,Tableau_Units[Units],Tableau_Units[code],"") | BK4: No | BL4: =_xlfn.XLOOKUP($BM$4,Tableau_SendMode[Send mode],Tableau_SendMode[Code],"") -> 0 | BM4: Don't send | BN4: =_xlfn.XLOOKUP($BO$4,Tableau_SendMode[Send mode],Tableau_SendMode[Code],"") -> 0 | BO4: Don't send | BP4: =_xlfn.XLOOKUP($BQ$4,Tableau_SendMode[Send mode],Tableau_SendMode[Code],"") -> 0 | BQ4: Don't send
A5: Example : | B5: SCGA-00890-V02.01-FR | C5: ProductName | D5: 484 | E5: Heating Ventilation and Air Conditioning equipment | F5: 504 | G5: Ventilation and/or Heating and/or Air Conditioning and/or Hot Water Heating | H5: 570 | I5: Multifunctions equipment | J5: 703 | K5: Balanced ventilation unit with heat pump | L5: Dual air flow unit 250 m3/h – reference TOP1234 | M5: Transfer 1 m3/h of air per hour for the ventilation and/or air treatment and/or smoke exhaust and/or filtration of a building over the reference lifetime of 17 years. | N5: 250 | O5: 2 | P5: m³/h | Q5: 44409 | R5: 2 | S5: PEP-PCR-ed4-2021 09 06 | T5: 6 | U5: PSR-0008-ed2.0-EN-2018 02 09 | V5: 17 | X5: europe | Y5: 510 903 510 905 510 907 510 912 | Z5: Other references : 510 903 - 510 905 - 510 907 - 510 912 | AA5: 3.2 | AB5: 3 | AC5: kg (kilogram) | AD5: 1 | AE5: kg | AF5: 1 | AG5: kg | AH5: 1.2 | AI5: kg | AJ5: 0.305 | AK5: 0.5075 | AL5: 0.1875 | AM5: =AL5+AK5+AJ5 -> 1 | AN5: 0.305 | AO5: 0.5075 | AP5: 0.1875 | AQ5: =AP5+AO5+AN5 -> 1 | AR5: xxxxx | AS5: xxxxx | AT5: xxxxx | AV5: email@domain.fr | AW5: xxxxx | AX5: xxxxx | AY5: email@domain.fr | AZ5: VH00 | BA5: xxxx | BB5: xxxx | BC5: xxxx | BD5: No | BE5: Yes | BG5: 1 | BH5: 13 | BI5: unit | BJ5: xxxx | BK5: No | BL5: 1 | BM5: Send Functional Unit | BN5: 0 | BO5: Don't send | BP5: 2 | BQ5: Send Declared Product
A6: Description : | B6: This is your unique PEP Registration Number | C6: This is your product Name | E6: First level of classification | G6: Second level of classification, depending on the first level | I6: Third level of classification, depending on second level | K6: Last level of classification, depending on third level | L6: The reference of the product used to produce the PEP | V6: Use Life-time in years | Y6: Commercial references covered by the PEP | Z6: Commercial references covered by the PEP as free text | AD6: PCR4 information | AE6: PCR4 information | AF6: PCR4 information | AG6: PCR4 information | AH6: PCR4 information | AI6: PCR4 information | AJ6: PCR4 information | AK6: PCR4 information | AL6: PCR4 information | AM6: Automatic | BF6: Only for Declared Product (BC column = Yes) | BG6: Only for Declared Product (BC column = Yes) | BI6: Only for Declared Product (BC column = Yes) | BJ6: Only for Declared Product (BC column = Yes) | BR6: Keywords linked to you declaration helping customers to search for you PEP
A7: Help : | B7: o "AAAA" : unique code of 4 alpha-numeric characters assigned to the applicant company. o "bbbbb" : Unique document number of 5 digits managed by the applicant Company o "V" = fixed character before the PEP version o "xx.yy": identification of the version of the document according to the rules defined :  "xx" version number "major" from 01 to 99  "yy": version number of "minor" from 01 to 99  The first version of a PEP begins with the number "01.01" o "cc": code of 2 characters for the language of the document according to ISO 639 | E7: You have to select the highest level available of classification. If there is sublevels avaiable when you choose a level, you have to select a sublevel. | L7: It's a single reference. This field is not for commercial references covered by the PEP. | Q7: You have to report here precisely the publication date specified in the PDF document | U7: If you used a PSR not listed here, please note that this template is updated once or twice a year. You will have more PSR available in the database registration, and you will be able to select it on the PEP Ecopassport© platform after importing this template. | Y7: Thoses two fields could be use simultaneously. The Reference Product (column L) will be automatically added in the covered products by list if you does'nt add it. | AZ7: "VH" -> fixed prefix "00" -> integer with 2 numbers | BB7: Choice of a submitter of the company to PEP ecopassport for registration. Leave empty if it's your own PEP account. | BM7: Only french PEP are allowed to be send to Inies Database. They must have all mandatory indicators filled. | BR7: .
A8: =CONCATENATE("Template version : ",'Ref_PCR-PSR-Zone'!J8," (updated on ",TEXT('Ref_PCR-PSR-Zone'!J9,"aaaa-mm-jj"),")") -> Template version : 1.18 (updated on 2026-05-06)

Sheet Indicators PCR-ed 2.1
A1: Codes | B1: unit | C1: Total (calculated) | D1: Total (declared) | E1: A1 | F1: A2 | G1: A3 | H1: A4 | I1: A5
A2: Indicators | E2: Manufacturing | F2: Distribution | G2: Installation | H2: Use | I2: End of Life
A3: Global warming potential | B3: g.equivalent.CO2 | C3: =SUM(E3:I3) -> 0
A4: Stratospheric Ozone depletion | B4: g.equivalent.CFC-11 | C4: =SUM(E4:I4) -> 0
A5: Water eutrophication | B5: g.equivalent.P04 3- | C5: =SUM(E5:I5) -> 0
A6: Photochemical Ozone Creation | B6: g.equivalent.C2H4 | C6: =SUM(E6:I6) -> 0
A7: Air acidification | B7: g.equivalent.H+ | C7: =SUM(E7:I7) -> 0
A8: Energy depletion | B8: MJ | C8: =SUM(E8:I8) -> 0
A9: Water Depletion | B9: dm3 | C9: =SUM(E9:I9) -> 0
A10: Raw material depletion | B10: year-1 | C10: =SUM(E10:I10) -> 0
A11: Air toxicity | B11: m3 | C11: =SUM(E11:I11) -> 0
A12: Water toxicity | B12: m3 | C12: =SUM(E12:I12) -> 0
A13: Hazardous waste production | B13: kg | C13: =SUM(E13:I13) -> 0

Sheet Indicators PCR-ed 3
A1: Indicators | B1: unit | C1: Total | D1: Manufacturing | E1: Distribution | F1: Installation | G1: Use | H1: End of Life | I1: B1 | J1: B2 | K1: B3 | L1: B4 | M1: B5 | N1: B6 | O1: B7
A2: Global warming | B2: kg.equivalent.CO2
A3: Ozone depletion | B3: kg.equivalent.CFC-11
A4: Acidification of soil and water | B4: kg.equivalent.SO2
A5: Water eutrophication | B5: kg.equivalent.P04 3-
A6: Photochemical Ozone formation | B6: kg.equivalent.C2H4
A7: Depletion of abiotic resources - elements | B7: kg.equivalent.Sb
A8: Depletion of abiotic resources - fossil fuelss | B8: MJ
A9: Water pollution | B9: m3
A10: Air pollution | B10: m3
A11: Use of renewable primary energy, excluding renewable primary energy resources used as raw materials | B11: MJ
A12: Use of renewable primary energy resources used as raw materials | B12: MJ
A13: Total use of renewable primary energy resources (primary energy and primary energy resources used as raw materials) | B13: MJ
... A28: Total use of primary energy during the life cycle | B28: MJ

Sheet Indicators PCR-ed 3 - Decl.Prod
A1: Indicators | B1: unit | C1: Total | D1: Manufacturing | E1: Distribution | F1: Installation | G1: Use | H1: End of Life | I1: B1 | J1: B2 | K1: B3 | L1: B4 | M1: B5 | N1: B6 | O1: B7
A2: Global warming | B2: kg.equivalent.CO2
A3: Ozone depletion | B3: kg.equivalent.CFC-11
A4: Acidification of soil and water | B4: kg.equivalent.SO2
A5: Water eutrophication | B5: kg.equivalent.P04 3-
A6: Photochemical Ozone formation | B6: kg.equivalent.C2H4
A7: Depletion of abiotic resources - elements | B7: kg.equivalent.Sb
A8: Depletion of abiotic resources - fossil fuelss | B8: MJ
A9: Water pollution | B9: m3
A10: Air pollution | B10: m3
A11: Use of renewable primary energy, excluding renewable primary energy resources used as raw materials | B11: MJ
A12: Use of renewable primary energy resources used as raw materials | B12: MJ
A13: Total use of renewable primary energy resources (primary energy and primary energy resources used as raw materials) | B13: MJ
... A28: Total use of primary energy during the life cycle | B28: MJ

Sheet Indicators PCR-ed 4
E1: ID | G1: 1 | H1: 2 | I1: 3 | J1: 4 | K1: 5 | L1: 6 | M1: 7 | N1: 8 | O1: 9 | P1: 10 | Q1: 11 | R1: 12 | S1: 13 | T1: 14
H2: A1+A2+A3 | I2: A4 | J2: A5 | K2: B stage | L2: C stage | M2: B1 | N2: B2 | O2: B3 | P2: B4 | Q2: B5 | R2: B6 | S2: B7 | T2: D
C3: ID | D3: Indicators | E3: unit | F3: Total (calculated) | G3: Total | H3: Manufacturing stage | I3: Distribution stage | J3: Installation stage | K3: Use stage | L3: End of Life stage | M3: Use/Application | N3: Use/Maintenance | O3: Use/Repair | P3: Use/Replacement | Q3: Use/Refurbishment | R3: Use/Operational Energy Use | S3: Use/Operational Water Use | T3: Ben./loads byd system bound.
A4: Environmental impact | C4: 24 | D4: Climate change - total | E4: kg CO2 eq. | F4: =SUM(H4:L4) -> 0
C5: 25 | D5: Climate change - fossil fuels | E5: kg CO2 eq. | F5: =SUM(H5:L5) -> 0
C6: 26 | D6: Climate change - biogenics | E6: kg CO2 eq. | F6: =SUM(H6:L6) -> 0
C7: 27 | D7: Climate change - land use and land use transformation | E7: kg CO2 eq. | F7: =SUM(H7:L7) -> 0
C8: 13 | D8: Ozone depletion | E8: kg.equivalent.CFC-11 | F8: =SUM(H8:L8) -> 0
C9: 15 | D9: Acidification (AP) | E9: mole of H+ equiv | F9: =SUM(H9:L9) -> 0
C10: 17 | D10: Freshwater eutrophication | E10: kg P eq. | F10: =SUM(H10:L10) -> 0
C11: 18 | D11: Marine aquatic eutrophication | E11: kg of N equiv | F11: =SUM(H11:L11) -> 0
C12: 19 | D12: Terrestrial eutrophication | E12: mole of N equiv | F12: =SUM(H12:L12) -> 0
C13: 21 | D13: Photochemical ozone formation | E13: kg of NMVOC equiv | F13: =SUM(H13:L13) -> 0
C14: 22 | D14: Depletion of abiotic resources - elements | E14: kg.equivalent.Sb | F14: =SUM(H14:L14) -> 0
C15: 23 | D15: Depletion of abiotic resources - fossil fuels | E15: MJ | F15: =SUM(H15:L15) -> 0
C16: 28 | D16: Water scarcity | E16: m3 of equiv. deprivation worldwide | F16: =SUM(H16:L16) -> 0
... C22: 34 | D22: Impacts related to land use/soil quality | E22: - | F22: =SUM(H22:L22) -> 0
A23: Inventory flows indicators | B23: Resource use indicators | C23: 37 | D23: Use of renewable primary energy, excluding renewable primary energy resources used as raw materials | E23: MJ | F23: =SUM(H23:L23) -> 0
C24: 38 | D24: Use of renewable primary energy resources used as raw materials | E24: MJ | F24: =SUM(H24:L24) -> 0
C25: 39 | D25: Total use of renewable primary energy resources (primary energy and primary energy resources used as raw materials) | E25: MJ | F25: =SUM(H25:L25) -> 0
C26: 40 | D26: Use of non-renewable primary energy, excluding non-renewable primary energy resources used as raw materials | E26: MJ | F26: =SUM(H26:L26) -> 0
C27: 41 | D27: Use of non-renewable primary energy resources used as raw materials | E27: MJ | F27: =SUM(H27:L27) -> 0
C28: 42 | D28: Total use of non-renewable primary energy resources (primary energy and primary energy resources used as raw materials) | E28: MJ | F28: =SUM(H28:L28) -> 0
B29: Indicators describing the use of secondary materials, water and energy resources (e.g. waste combustion) | C29: 43 | D29: Use of secondary materials | E29: kg | F29: =SUM(H29:L29) -> 0
C30: 44 | D30: Use of renewable secondary fuels | E30: MJ | F30: =SUM(H30:L30) -> 0
C31: 45 | D31: Use of non-renewable secondary fuels | E31: MJ | F31: =SUM(H31:L31) -> 0
C32: 46 | D32: Net use of fresh water | E32: m3 | F32: =SUM(H32:L32) -> 0
C33: 56 | D33: Total use of primary energy during the life cycle | E33: MJ | F33: =SUM(H33:L33) -> 0
B34: Waste category indicators | C34: 47 | D34: Hazardous waste disposed of | E34: kg | F34: =SUM(H34:L34) -> 0
C35: 48 | D35: Non-hazardous waste disposed of | E35: kg | F35: =SUM(H35:L35) -> 0
C36: 49 | D36: Radioactive waste disposed of | E36: kg | F36: =SUM(H36:L36) -> 0
B37: Output flow indicators | C37: 50 | D37: Components for re-use | E37: kg | F37: =SUM(H37:L37) -> 0
C38: 51 | D38: Materials for recycling | E38: kg | F38: =SUM(H38:L38) -> 0
C39: 52 | D39: Materials for energy recovery | E39: kg | F39: =SUM(H39:L39) -> 0
C40: 53 | D40: Exported energy | E40: MJ by energy vector | F40: =SUM(H40:L40) -> 0
B41: Other indicators | C41: 54 | D41: Biogenic carbon content of the product | E41: kg of C. | F41: =SUM(H41:L41) -> 0
C42: 55 | D42: Biogenic carbon content of the associated packaging | E42: kg of C. | F42: =SUM(H42:L42) -> 0

Sheet Indicators PCR-ed 4 - Decl.Prod
E1: ID | G1: 1 | H1: 2 | I1: 3 | J1: 4 | K1: 5 | L1: 6 | M1: 7 | N1: 8 | O1: 9 | P1: 10 | Q1: 11 | R1: 12 | S1: 13 | T1: 14
H2: A1+A2+A3 | I2: A4 | J2: A5 | K2: B stage | L2: C stage | M2: B1 | N2: B2 | O2: B3 | P2: B4 | Q2: B5 | R2: B6 | S2: B7 | T2: D
C3: ID | D3: Indicators | E3: unit | F3: Total (calculated) | G3: Total | H3: Manufacturing stage | I3: Distribution stage | J3: Installation stage | K3: Use stage | L3: End of Life stage | M3: Use/Application | N3: Use/Maintenance | O3: Use/Repair | P3: Use/Replacement | Q3: Use/Refurbishment | R3: Use/Operational Energy Use | S3: Use/Operational Water Use | T3: Ben./loads byd system bound.
A4: Environmental impact | C4: 24 | D4: Climate change - total | E4: kg CO2 eq. | F4: =SUM(H4:L4) -> 0
C5: 25 | D5: Climate change - fossil fuels | E5: kg CO2 eq. | F5: =SUM(H5:L5) -> 0
C6: 26 | D6: Climate change - biogenics | E6: kg CO2 eq. | F6: =SUM(H6:L6) -> 0
C7: 27 | D7: Climate change - land use and land use transformation | E7: kg CO2 eq. | F7: =SUM(H7:L7) -> 0
C8: 13 | D8: Ozone depletion | E8: kg.equivalent.CFC-11 | F8: =SUM(H8:L8) -> 0
C9: 15 | D9: Acidification (AP) | E9: mole of H+ equiv | F9: =SUM(H9:L9) -> 0
C10: 17 | D10: Freshwater eutrophication | E10: kg P eq. | F10: =SUM(H10:L10) -> 0
C11: 18 | D11: Marine aquatic eutrophication | E11: kg of N equiv | F11: =SUM(H11:L11) -> 0
C12: 19 | D12: Terrestrial eutrophication | E12: mole of N equiv | F12: =SUM(H12:L12) -> 0
C13: 21 | D13: Photochemical ozone formation | E13: kg of NMVOC equiv | F13: =SUM(H13:L13) -> 0
C14: 22 | D14: Depletion of abiotic resources - elements | E14: kg.equivalent.Sb | F14: =SUM(H14:L14) -> 0
C15: 23 | D15: Depletion of abiotic resources - fossil fuels | E15: MJ | F15: =SUM(H15:L15) -> 0
C16: 28 | D16: Water scarcity | E16: m3 of equiv. deprivation worldwide | F16: =SUM(H16:L16) -> 0
... C22: 34 | D22: Impacts related to land use/soil quality | E22: - | F22: =SUM(H22:L22) -> 0
A23: Inventory flows indicators | B23: Resource use indicators | C23: 37 | D23: Use of renewable primary energy, excluding renewable primary energy resources used as raw materials | E23: MJ | F23: =SUM(H23:L23) -> 0
C24: 38 | D24: Use of renewable primary energy resources used as raw materials | E24: MJ | F24: =SUM(H24:L24) -> 0
C25: 39 | D25: Total use of renewable primary energy resources (primary energy and primary energy resources used as raw materials) | E25: MJ | F25: =SUM(H25:L25) -> 0
C26: 40 | D26: Use of non-renewable primary energy, excluding non-renewable primary energy resources used as raw materials | E26: MJ | F26: =SUM(H26:L26) -> 0
C27: 41 | D27: Use of non-renewable primary energy resources used as raw materials | E27: MJ | F27: =SUM(H27:L27) -> 0
C28: 42 | D28: Total use of non-renewable primary energy resources (primary energy and primary energy resources used as raw materials) | E28: MJ | F28: =SUM(H28:L28) -> 0
B29: Indicators describing the use of secondary materials, water and energy resources (e.g. waste combustion) | C29: 43 | D29: Use of secondary materials | E29: kg | F29: =SUM(H29:L29) -> 0
C30: 44 | D30: Use of renewable secondary fuels | E30: MJ | F30: =SUM(H30:L30) -> 0
C31: 45 | D31: Use of non-renewable secondary fuels | E31: MJ | F31: =SUM(H31:L31) -> 0
C32: 46 | D32: Net use of fresh water | E32: m3 | F32: =SUM(H32:L32) -> 0
C33: 56 | D33: Total use of primary energy during the life cycle | E33: MJ | F33: =SUM(H33:L33) -> 0
B34: Waste category indicators | C34: 47 | D34: Hazardous waste disposed of | E34: kg | F34: =SUM(H34:L34) -> 0
C35: 48 | D35: Non-hazardous waste disposed of | E35: kg | F35: =SUM(H35:L35) -> 0
C36: 49 | D36: Radioactive waste disposed of | E36: kg | F36: =SUM(H36:L36) -> 0
B37: Output flow indicators | C37: 50 | D37: Components for re-use | E37: kg | F37: =SUM(H37:L37) -> 0
C38: 51 | D38: Materials for recycling | E38: kg | F38: =SUM(H38:L38) -> 0
C39: 52 | D39: Materials for energy recovery | E39: kg | F39: =SUM(H39:L39) -> 0
C40: 53 | D40: Exported energy | E40: MJ by energy vector | F40: =SUM(H40:L40) -> 0
B41: Other indicators | C41: 54 | D41: Biogenic carbon content of the product | E41: kg of C. | F41: =SUM(H41:L41) -> 0
C42: 55 | D42: Biogenic carbon content of the associated packaging | E42: kg of C. | F42: =SUM(H42:L42) -> 0

Sheet Level1
A1: {=_xlfn._xlws.SORT(_xlfn._xlws.FILTER(Tableau_Nomenclature[],Tableau_Nomenclature[tree_level]=1,""),2)} -> 483 | B1: building security | C1: 479 | D1: 1 | E1: true
A2: 27000000 | B2: Electric engineering, automation, process control engineering | C2: 479 | D2: 1 | E2: true
A3: 952 | B3: EV Charging Infrastructures | C3: 479 | D3: 1 | E3: true
A4: 484 | B4: Heating, ventilation and air conditioning equipement | C4: 479 | D4: 1 | E4: true
A5: 480 | B5: Installation wiring devices for electric power and communication networks (= 63 amperes) | C5: 479 | D5: 1 | E5: true
A6: 773 | B6: Lighting products | C6: 479 | D6: 1 | E6: true
A7: 485 | B7: Local electricty production | C7: 479 | D7: 1 | E7: true
A8: 486 | B8: Others | C8: 479 | D8: 1 | E8: false
A9: 482 | B9: people safety and access control | C9: 479 | D9: 1 | E9: true
A10: 1051 | B10: Transportation of people or goods in buildings | C10: 479 | D10: 1 | E10: true
A11: 481 | B11: Wires and cables | C11: 479 | D11: 1 | E11: true

Sheet Level2
A1: {=_xlfn._xlws.SORT(_xlfn._xlws.FILTER(Tableau_Nomenclature[],Tableau_Nomenclature[idParent]='PEP Declaration'!D4,""),2)} -> 479 | B1: Electric and electronic equipment | C1: 0 | D1: 0 | E1: true

Sheet Level3
A1: {=_xlfn._xlws.SORT(_xlfn._xlws.FILTER(Tableau_Nomenclature[],Tableau_Nomenclature[idParent]='PEP Declaration'!F4,""),2)} -> 479 | B1: Electric and electronic equipment | C1: 0 | D1: 0 | E1: true

Sheet Level4
A1: {=_xlfn._xlws.SORT(_xlfn._xlws.FILTER(Tableau_Nomenclature[],Tableau_Nomenclature[idParent]='PEP Declaration'!H4,""),2)} -> 479 | B1: Electric and electronic equipment | C1: 0 | D1: 0 | E1: true

Sheet Ref_FuncUnit
A1: Functional Units | D1: Mass Units
A2: code | B2: Units | D2: code | E2: Units
A3: 1 | B3: dm² | D3: 3 | E3: kg
A4: 2 | B4: m²
A5: 3 | B5: kg
A6: 4 | B6: m³ | H6: Pour ajouter une ligne aux tableaux :
A7: 5 | B7: m | H7: Entrer la valeur désirée dans la première cellule disponible en dessous du tableau
A8: 6 | B8: MJ | H8: Sélectionner n'importe quelle cellule valide du tableau actuel
A9: 7 | B9: kWh | H9: Onglet "Conception de la table" -> "Redimensionner" puis étendre la sélection pour inclure la ligne ajoutée
A10: 8 | B10: L
A11: 9 | B11: g
A12: 10 | B12: cm
A13: 11 | B13: ml
A14: 13 | B14: unit
A15: 18 | B15: mg
A16: 19 | B16: mm³
A17: 22 | B17: g/m²
A18: 25 | B18: kg/m²
A19: 26 | B19: kWhep
A20: 37 | B20: km
A21: 38 | B21: mL
... A32: 73 | B32: m³/s

Sheet Ref_PCR-PSR-Zone
A2: PCR Versions | D2: PSR Versions | G2: Geo Zones | J2: Boolean
A3: Code | B3: PCR | D3: Code | E3: PSR | G3: Code | H3: Zone | J3: Boolean | L3: Pour ajouter une ligne aux tableaux :
A4: 1 | B4: PEP-PCR-ed2.1-2012 12 11 | D4: 0 | E4: No PSR | G4: 39 | H4: ABW | J4: Yes | L4: Entrer la valeur désirée dans la première cellule disponible en dessous du tableau
A5: 2 | B5: PEP-PCR-ed3-2015 04 02 | D5: 1 | E5: PSR-0001-ed2-2015 01 20 | G5: 26 | H5: AFG | J5: No | L5: Sélectionner n'importe quelle cellule valide du tableau actuel
A6: 3 | B6: PEP-PCR-ed4-2021 09 06 | D6: 2 | E6: PSR-0001-ed3-2015 10 16 | G6: 2 | H6: Africa | L6: Onglet "Conception de la table" -> "Redimensionner" puis étendre la sélection pour inclure la ligne ajoutée
D7: 34 | E7: PSR-0001-ed4-2022 11 16 | G7: 32 | H7: AGO | J7: Template Version
D8: 3 | E8: PSR-0002-ed1.1-2015 05 26 | G8: 33 | H8: AIA | J8: 1.18
D9: 4 | E9: PSR-0002-ed2-2017 10 17 | G9: 120 | H9: ALA | J9: 46148
D10: 36 | E10: PSR-0002-ed3-2023 06 06 | G10: 28 | H10: ALB
D11: 6 | E11: PSR-0003-ed1-2012 02 02 | G11: 3 | H11: America
D12: 5 | E12: PSR-0003-ed1.1-2015 10 16 | G12: 31 | H12: AND
D13: 37 | E13: PSR-0003-ed2-2023 06 06 | G13: 83 | H13: ARE
D14: 51 | E14: PSR-0003-ed2.1-2023 12 08 | G14: 37 | H14: ARG
D15: 8 | E15: PSR-0004-ed2-2014 04 08 | G15: 38 | H15: ARM
D16: 7 | E16: PSR-0004-ed2.1-2015 05 26 | G16: 4 | H16: Asia
A17: Export | B17: Export | D17: 9 | E17: PSR-0004-ed3-2018 02 09 | G17: 230 | H17: ASM
A18: Code | B18: Send mode | D18: 38 | E18: PSR-0004-ed4-2019 03 14 | G18: 34 | H18: ATA
A19: 0 | B19: Don't send | D19: 10 | E19: PSR-0004-ed4.0-EN-2019 03 14 | G19: 253 | H19: ATF
A20: 1 | B20: Send Functional Unit | D20: 46 | E20: PSR-0004-ed5.0-2023 10 19 | G20: 35 | H20: ATG
A21: 2 | B21: Send Declared Product | D21: 72 | E21: PSR-0004-ed5.1-2025 06 17 | G21: 40 | H21: AUS
D22: 11 | E22: PSR-0005-ed1-2012 12 11 | G22: 41 | H22: AUT
D23: 12 | E23: PSR-0005-ed2-2016 03 29 | G23: 42 | H23: AZE
D24: 35 | E24: PSR-0005-ed3-2023 06 06 | G24: 60 | H24: BDI
D25: 52 | E25: PSR-0005-ed3.1-2023 12 08 | G25: 47 | H25: BEL
D26: 14 | E26: PSR-0006-ed1-2013 02 12 | G26: 49 | H26: BEN
D27: 13 | E27: PSR-0006-ed1.1-2015 10 16 | G27: 202 | H27: BES
D28: 39 | E28: PSR-0006-ed2-2023 06 06 | G28: 59 | H28: BFA
D29: 53 | E29: PSR-0006-ed2.1-2023 12 08 | G29: 45 | H29: BGD
D30: 16 | E30: PSR-0007-ed1-2013 04 09 | G30: 58 | H30: BGR
D31: 15 | E31: PSR-0007-ed1.1-2015 10 16 | G31: 44 | H31: BHR
D32: 40 | E32: PSR-0007-ed2-2023 06 06 | G32: 43 | H32: BHS
D33: 54 | E33: PSR-0007-ed2.1-2023 12 08 | G33: 54 | H33: BIH
... D78: 76 | E78: PSR-PSR-0020 - ACCESS CONTROL PRODUCTS-ed1-2025 11 03 | G78: 21 | H78: East Europa
G79: 84 | H79: ECU
G80: 82 | H80: EGY
G81: 85 | H81: ERI
G82: 218 | H82: ESH
G83: 86 | H83: ESP
G84: 87 | H84: EST
G85: 91 | H85: ETH
...

Sheet Nomenclature
B2: id | C2: EN-Designation | D2: idParent | E2: tree_level | F2: has_children
B3: 479 | C3: Electric and electronic equipment | E3: 0 | F3: true
B4: 480 | C4: Installation wiring devices for electric power and communication networks (= 63 amperes) | D4: 479 | E4: 1 | F4: true
B5: 487 | C5: Wall mounted swithgear and controlgear | D5: 480 | E5: 2 | F5: true
B6: 521 | C6: Automation devices | D6: 487 | E6: 3 | F6: true
B7: 581 | C7: Presence detector | D7: 521 | E7: 4 | F7: false
B8: 582 | C8: Thermostats, programmable thermostats, hygrostats | D8: 521 | E8: 4 | F8: false
B9: 583 | C9: Dimmer | D9: 521 | E9: 4 | F9: false
B10: 522 | C10: Flush mounting box | D10: 487 | E10: 3 | F10: true
B11: 584 | C11: Flush mounting box on drywall | D11: 522 | E11: 4 | F11: false
B12: 585 | C12: Flush mounting box for masonry | D12: 522 | E12: 4 | F12: false
B13: 523 | C13: Controls | D13: 487 | E13: 3 | F13: true
B14: 586 | C14: Switch | D14: 523 | E14: 4 | F14: false
B15: 587 | C15: Push button | D15: 523 | E15: 4 | F15: false
... B402: 965 | C402: Others | D402: 962 | E402: 3 | F402: false
